Workbook

Sheet AAPL_TSLA
A1: ID | B1: ticker | C1: Date | D1: Open | E1: High | F1: Low | G1: Close | H1: Volume | I1: Daily_Return | J1: Return_Excel | K1: SMA_20 | L1: SMA_50 | M1: VOL_20 | N1: Trend_20_50 | O1: Max_Close | P1: Drawdown | Q1: Date_Helper | R1: Vol_Bucket
A2: 1 | B2: AAPL | C2: 2020-11-27 | D2: 113.475 | E2: 114.371 | F2: 113.135 | G2: 113.495 | H2: 46691300 | N2: =IF(OR(ISBLANK(K2),ISBLANK(L2)),"",IF(K2>L2,"Uptrend","Downtrend")) | O2: =MAX(G2,O1) -> 113.495 | P2: =G2/O2 - 1 -> 0 | Q2: =TEXT(C2, "YYYY-MM") -> 2020-11 | R2: =IF(M2="","", IF(M2<0.015,"Low", IF(M2<0.03,"Medium","High")))
A3: 2 | B3: AAPL | C3: 2020-11-30 | D3: 113.865 | E3: 117.759 | F3: 113.709 | G3: 115.89 | H3: 169410200 | I3: 0.0210997 | J3: =(G3/G2) - 1 -> 0.021102251 | N3: =IF(OR(ISBLANK(K3),ISBLANK(L3)),"",IF(K3>L3,"Uptrend","Downtrend")) | O3: =MAX(G3,O2) -> 115.89 | P3: =G3/O3 - 1 -> 0 | Q3: =TEXT(C3, "YYYY-MM") -> 2020-11 | R3: =IF(M3="","", IF(M3<0.015,"Low", IF(M3<0.03,"Medium","High")))
A4: 3 | B4: AAPL | C4: 2020-12-01 | D4: 117.797 | E4: 120.192 | F4: 116.824 | G4: 119.462 | H4: 127728200 | I4: 0.0308273 | J4: =(G4/G3) - 1 -> 0.030822332 | N4: =IF(OR(ISBLANK(K4),ISBLANK(L4)),"",IF(K4>L4,"Uptrend","Downtrend")) | O4: =MAX(G4,O3) -> 119.462 | P4: =G4/O4 - 1 -> 0 | Q4: =TEXT(C4, "YYYY-MM") -> 2020-12 | R4: =IF(M4="","", IF(M4<0.015,"Low", IF(M4<0.03,"Medium","High")))
A5: 4 | B5: AAPL | C5: 2020-12-02 | D5: 118.781 | E5: 120.095 | F5: 117.681 | G5: 119.813 | H5: 89004200 | I5: 0.00293356 | J5: =(G5/G4) - 1 -> 0.0029381728 | N5: =IF(OR(ISBLANK(K5),ISBLANK(L5)),"",IF(K5>L5,"Uptrend","Downtrend")) | O5: =MAX(G5,O4) -> 119.813 | P5: =G5/O5 - 1 -> 0 | Q5: =TEXT(C5, "YYYY-MM") -> 2020-12 | R5: =IF(M5="","", IF(M5<0.015,"Low", IF(M5<0.03,"Medium","High")))
A6: 5 | B6: AAPL | C6: 2020-12-03 | D6: 120.241 | E6: 120.494 | F6: 118.966 | G6: 119.676 | H6: 78967600 | I6: -0.00113735 | J6: =(G6/G5) - 1 -> -0.0011434485 | N6: =IF(OR(ISBLANK(K6),ISBLANK(L6)),"",IF(K6>L6,"Uptrend","Downtrend")) | O6: =MAX(G6,O5) -> 119.813 | P6: =G6/O6 - 1 -> -0.0011434485 | Q6: =TEXT(C6, "YYYY-MM") -> 2020-12 | R6: =IF(M6="","", IF(M6<0.015,"Low", IF(M6<0.03,"Medium","High")))
A7: 6 | B7: AAPL | C7: 2020-12-04 | D7: 119.345 | E7: 119.598 | F7: 118.294 | G7: 119.005 | H7: 78260400 | I7: -0.00561258 | J7: =(G7/G6) - 1 -> -0.005606805 | N7: =IF(OR(ISBLANK(K7),ISBLANK(L7)),"",IF(K7>L7,"Uptrend","Downtrend")) | O7: =MAX(G7,O6) -> 119.813 | P7: =G7/O7 - 1 -> -0.0067438425 | Q7: =TEXT(C7, "YYYY-MM") -> 2020-12 | R7: =IF(M7="","", IF(M7<0.015,"Low", IF(M7<0.03,"Medium","High")))
A8: 7 | B8: AAPL | C8: 2020-12-07 | D8: 119.063 | E8: 121.263 | F8: 119.005 | G8: 120.465 | H8: 86712000 | I8: 0.01227 | J8: =(G8/G7) - 1 -> 0.012268392 | N8: =IF(OR(ISBLANK(K8),ISBLANK(L8)),"",IF(K8>L8,"Uptrend","Downtrend")) | O8: =MAX(G8,O7) -> 120.465 | P8: =G8/O8 - 1 -> 0 | Q8: =TEXT(C8, "YYYY-MM") -> 2020-12 | R8: =IF(M8="","", IF(M8<0.015,"Low", IF(M8<0.03,"Medium","High")))
A9: 8 | B9: AAPL | C9: 2020-12-08 | D9: 121.068 | E9: 121.662 | F9: 119.822 | G9: 121.078 | H9: 82225500 | I9: 0.00509083 | J9: =(G9/G8) - 1 -> 0.005088615 | N9: =IF(OR(ISBLANK(K9),ISBLANK(L9)),"",IF(K9>L9,"Uptrend","Downtrend")) | O9: =MAX(G9,O8) -> 121.078 | P9: =G9/O9 - 1 -> 0 | Q9: =TEXT(C9, "YYYY-MM") -> 2020-12 | R9: =IF(M9="","", IF(M9<0.015,"Low", IF(M9<0.03,"Medium","High")))
A10: 9 | B10: AAPL | C10: 2020-12-09 | D10: 121.224 | E10: 122.606 | F10: 117.788 | G10: 118.547 | H10: 115089200 | I10: -0.0209036 | J10: =(G10/G9) - 1 -> -0.02090388 | N10: =IF(OR(ISBLANK(K10),ISBLANK(L10)),"",IF(K10>L10,"Uptrend","Downtrend")) | O10: =MAX(G10,O9) -> 121.078 | P10: =G10/O10 - 1 -> -0.02090388 | Q10: =TEXT(C10, "YYYY-MM") -> 2020-12 | R10: =IF(M10="","", IF(M10<0.015,"Low", IF(M10<0.03,"Medium","High")))
A11: 10 | B11: AAPL | C11: 2020-12-10 | D11: 117.301 | E11: 120.582 | F11: 116.96 | G11: 119.968 | H11: 81312200 | I11: 0.0119888 | J11: =(G11/G10) - 1 -> 0.011986807 | N11: =IF(OR(ISBLANK(K11),ISBLANK(L11)),"",IF(K11>L11,"Uptrend","Downtrend")) | O11: =MAX(G11,O10) -> 121.078 | P11: =G11/O11 - 1 -> -0.009167644 | Q11: =TEXT(C11, "YYYY-MM") -> 2020-12 | R11: =IF(M11="","", IF(M11<0.015,"Low", IF(M11<0.03,"Medium","High")))
A12: 11 | B12: AAPL | C12: 2020-12-11 | D12: 119.18 | E12: 119.501 | F12: 117.35 | G12: 119.16 | H12: 86939800 | I12: -0.00673491 | J12: =(G12/G11) - 1 -> -0.0067351294 | N12: =IF(OR(ISBLANK(K12),ISBLANK(L12)),"",IF(K12>L12,"Uptrend","Downtrend")) | O12: =MAX(G12,O11) -> 121.078 | P12: =G12/O12 - 1 -> -0.015841028 | Q12: =TEXT(C12, "YYYY-MM") -> 2020-12 | R12: =IF(M12="","", IF(M12<0.015,"Low", IF(M12<0.03,"Medium","High")))
A13: 12 | B13: AAPL | C13: 2020-12-14 | D13: 119.345 | E13: 120.075 | F13: 118.313 | G13: 118.547 | H13: 79184500 | I13: -0.00514656 | J13: =(G13/G12) - 1 -> -0.0051443437 | N13: =IF(OR(ISBLANK(K13),ISBLANK(L13)),"",IF(K13>L13,"Uptrend","Downtrend")) | O13: =MAX(G13,O12) -> 121.078 | P13: =G13/O13 - 1 -> -0.02090388 | Q13: =TEXT(C13, "YYYY-MM") -> 2020-12 | R13: =IF(M13="","", IF(M13<0.015,"Low", IF(M13<0.03,"Medium","High")))
A14: 13 | B14: AAPL | C14: 2020-12-15 | D14: 121.039 | E14: 124.505 | F14: 120.835 | G14: 124.485 | H14: 157243700 | I14: 0.0500903 | J14: =(G14/G13) - 1 -> 0.050089838 | N14: =IF(OR(ISBLANK(K14),ISBLANK(L14)),"",IF(K14>L14,"Uptrend","Downtrend")) | O14: =MAX(G14,O13) -> 124.485 | P14: =G14/O14 - 1 -> 0 | Q14: =TEXT(C14, "YYYY-MM") -> 2020-12 | R14: =IF(M14="","", IF(M14<0.015,"Low", IF(M14<0.03,"Medium","High")))
... A20: 19 | B20: AAPL | C20: 2020-12-23 | D20: 128.651 | E20: 128.914 | F20: 127.308 | G20: 127.483 | H20: 88223700 | I20: -0.0069761 | J20: =(G20/G19) - 1 -> -0.0069793346 | N20: =IF(OR(ISBLANK(K20),ISBLANK(L20)),"",IF(K20>L20,"Uptrend","Downtrend")) | O20: =MAX(G20,O19) -> 128.379 | P20: =G20/O20 - 1 -> -0.0069793346 | Q20: =TEXT(C20, "YYYY-MM") -> 2020-12 | R20: =IF(M20="","", IF(M20<0.015,"Low", IF(M20<0.03,"Medium","High")))
A21: 20 | B21: AAPL | C21: 2020-12-24 | D21: 127.834 | E21: 129.917 | F21: 127.62 | G21: 128.466 | H21: 54930100 | I21: 0.00771226 | J21: =(G21/G20) - 1 -> 0.007710832 | K21: =AVERAGE(G2:G21) -> 121.5871 | N21: =IF(OR(ISBLANK(K21),ISBLANK(L21)),"",IF(K21>L21,"Uptrend","Downtrend")) | O21: =MAX(G21,O20) -> 128.466 | P21: =G21/O21 - 1 -> 0 | Q21: =TEXT(C21, "YYYY-MM") -> 2020-12 | R21: =IF(M21="","", IF(M21<0.015,"Low", IF(M21<0.03,"Medium","High")))
A22: 21 | B22: AAPL | C22: 2020-12-28 | D22: 130.433 | E22: 133.694 | F22: 129.966 | G22: 133.061 | H22: 124486200 | I22: 0.0357658 | J22: =(G22/G21) - 1 -> 0.035768219 | K22: =AVERAGE(G3:G22) -> 122.5654 | M22: =_xlfn.STDEV.S(J3:J22) -> 0.017921938 | N22: =IF(OR(ISBLANK(K22),ISBLANK(L22)),"",IF(K22>L22,"Uptrend","Downtrend")) | O22: =MAX(G22,O21) -> 133.061 | P22: =G22/O22 - 1 -> 0 | Q22: =TEXT(C22, "YYYY-MM") -> 2020-12 | R22: =IF(M22="","", IF(M22<0.015,"Low", IF(M22<0.03,"Medium","High"))) -> Medium
A23: 22 | B23: AAPL | C23: 2020-12-29 | D23: 134.385 | E23: 135.105 | F23: 130.774 | G23: 131.289 | H23: 121047300 | I23: -0.013315 | J23: =(G23/G22) - 1 -> -0.0133172 | K23: =AVERAGE(G4:G23) -> 123.33535 | M23: =_xlfn.STDEV.S(J4:J23) -> 0.018260536 | N23: =IF(OR(ISBLANK(K23),ISBLANK(L23)),"",IF(K23>L23,"Uptrend","Downtrend")) | O23: =MAX(G23,O22) -> 133.061 | P23: =G23/O23 - 1 -> -0.0133172 | Q23: =TEXT(C23, "YYYY-MM") -> 2020-12 | R23: =IF(M23="","", IF(M23<0.015,"Low", IF(M23<0.03,"Medium","High"))) -> Medium
A24: 23 | B24: AAPL | C24: 2020-12-30 | D24: 131.981 | E24: 132.38 | F24: 129.858 | G24: 130.17 | H24: 96452100 | I24: -0.00852689 | J24: =(G24/G23) - 1 -> -0.0085231817 | K24: =AVERAGE(G5:G24) -> 123.87075 | M24: =_xlfn.STDEV.S(J5:J24) -> 0.017599948 | N24: =IF(OR(ISBLANK(K24),ISBLANK(L24)),"",IF(K24>L24,"Uptrend","Downtrend")) | O24: =MAX(G24,O23) -> 133.061 | P24: =G24/O24 - 1 -> -0.021726877 | Q24: =TEXT(C24, "YYYY-MM") -> 2020-12 | R24: =IF(M24="","", IF(M24<0.015,"Low", IF(M24<0.03,"Medium","High"))) -> Medium
A25: 24 | B25: AAPL | C25: 2020-12-31 | D25: 130.52 | E25: 131.163 | F25: 128.223 | G25: 129.167 | H25: 99116600 | I25: -0.00770231 | J25: =(G25/G24) - 1 -> -0.0077053084 | K25: =AVERAGE(G6:G25) -> 124.33845 | M25: =_xlfn.STDEV.S(J6:J25) -> 0.017807636 | N25: =IF(OR(ISBLANK(K25),ISBLANK(L25)),"",IF(K25>L25,"Uptrend","Downtrend")) | O25: =MAX(G25,O24) -> 133.061 | P25: =G25/O25 - 1 -> -0.029264773 | Q25: =TEXT(C25, "YYYY-MM") -> 2020-12 | R25: =IF(M25="","", IF(M25<0.015,"Low", IF(M25<0.03,"Medium","High"))) -> Medium
A26: 25 | B26: AAPL | C26: 2021-01-04 | D26: 129.975 | E26: 130.063 | F26: 123.395 | G26: 125.974 | H26: 143301900 | I26: -0.0247195 | J26: =(G26/G25) - 1 -> -0.024719936 | K26: =AVERAGE(G7:G26) -> 124.65335 | M26: =_xlfn.STDEV.S(J7:J26) -> 0.018906501 | N26: =IF(OR(ISBLANK(K26),ISBLANK(L26)),"",IF(K26>L26,"Uptrend","Downtrend")) | O26: =MAX(G26,O25) -> 133.061 | P26: =G26/O26 - 1 -> -0.053261286 | Q26: =TEXT(C26, "YYYY-MM") -> 2021-01 | R26: =IF(M26="","", IF(M26<0.015,"Low", IF(M26<0.03,"Medium","High"))) -> Medium
A27: 26 | B27: AAPL | C27: 2021-01-05 | D27: 125.468 | E27: 128.243 | F27: 125.021 | G27: 127.532 | H27: 97664900 | I27: 0.0123643 | J27: =(G27/G26) - 1 -> 0.012367631 | K27: =AVERAGE(G8:G27) -> 125.0797 | M27: =_xlfn.STDEV.S(J8:J27) -> 0.018916298 | N27: =IF(OR(ISBLANK(K27),ISBLANK(L27)),"",IF(K27>L27,"Uptrend","Downtrend")) | O27: =MAX(G27,O26) -> 133.061 | P27: =G27/O27 - 1 -> -0.041552371 | Q27: =TEXT(C27, "YYYY-MM") -> 2021-01 | R27: =IF(M27="","", IF(M27<0.015,"Low", IF(M27<0.03,"Medium","High"))) -> Medium
A28: 27 | B28: AAPL | C28: 2021-01-06 | D28: 124.329 | E28: 127.571 | F28: 123.025 | G28: 123.239 | H28: 155088000 | I28: -0.0336618 | J28: =(G28/G27) - 1 -> -0.03366214 | K28: =AVERAGE(G9:G28) -> 125.2184 | M28: =_xlfn.STDEV.S(J9:J28) -> 0.020531956 | N28: =IF(OR(ISBLANK(K28),ISBLANK(L28)),"",IF(K28>L28,"Uptrend","Downtrend")) | O28: =MAX(G28,O27) -> 133.061 | P28: =G28/O28 - 1 -> -0.073815769 | Q28: =TEXT(C28, "YYYY-MM") -> 2021-01 | R28: =IF(M28="","", IF(M28<0.015,"Low", IF(M28<0.03,"Medium","High"))) -> Medium
A29: 28 | B29: AAPL | C29: 2021-01-07 | D29: 124.952 | E29: 128.136 | F29: 124.466 | G29: 127.444 | H29: 109578200 | I29: 0.0341232 | J29: =(G29/G28) - 1 -> 0.034120692 | K29: =AVERAGE(G10:G29) -> 125.5367 | M29: =_xlfn.STDEV.S(J10:J29) -> 0.021798348 | N29: =IF(OR(ISBLANK(K29),ISBLANK(L29)),"",IF(K29>L29,"Uptrend","Downtrend")) | O29: =MAX(G29,O28) -> 133.061 | P29: =G29/O29 - 1 -> -0.042213722 | Q29: =TEXT(C29, "YYYY-MM") -> 2021-01 | R29: =IF(M29="","", IF(M29<0.015,"Low", IF(M29<0.03,"Medium","High"))) -> Medium
A30: 29 | B30: AAPL | C30: 2021-01-08 | D30: 128.914 | E30: 129.109 | F30: 126.773 | G30: 128.544 | H30: 105158200 | I30: 0.00863126 | J30: =(G30/G29) - 1 -> 0.008631242 | K30: =AVERAGE(G11:G30) -> 126.03655 | M30: =_xlfn.STDEV.S(J11:J30) -> 0.02109796 | N30: =IF(OR(ISBLANK(K30),ISBLANK(L30)),"",IF(K30>L30,"Uptrend","Downtrend")) | O30: =MAX(G30,O29) -> 133.061 | P30: =G30/O30 - 1 -> -0.033946836 | Q30: =TEXT(C30, "YYYY-MM") -> 2021-01 | R30: =IF(M30="","", IF(M30<0.015,"Low", IF(M30<0.03,"Medium","High"))) -> Medium
A31: 30 | B31: AAPL | C31: 2021-01-11 | D31: 125.76 | E31: 126.714 | F31: 125.089 | G31: 125.556 | H31: 100384500 | I31: -0.0232489 | J31: =(G31/G30) - 1 -> -0.023244959 | K31: =AVERAGE(G12:G31) -> 126.31595 | M31: =_xlfn.STDEV.S(J12:J31) -> 0.021875865 | N31: =IF(OR(ISBLANK(K31),ISBLANK(L31)),"",IF(K31>L31,"Uptrend","Downtrend")) | O31: =MAX(G31,O30) -> 133.061 | P31: =G31/O31 - 1 -> -0.056402703 | Q31: =TEXT(C31, "YYYY-MM") -> 2021-01 | R31: =IF(M31="","", IF(M31<0.015,"Low", IF(M31<0.03,"Medium","High"))) -> Medium
A32: 31 | B32: AAPL | C32: 2021-01-12 | D32: 125.089 | E32: 126.247 | F32: 123.492 | G32: 125.381 | H32: 91951100 | I32: -0.00139547 | J32: =(G32/G31) - 1 -> -0.0013938004 | K32: =AVERAGE(G13:G32) -> 126.627 | M32: =_xlfn.STDEV.S(J13:J32) -> 0.021789566 | N32: =IF(OR(ISBLANK(K32),ISBLANK(L32)),"",IF(K32>L32,"Uptrend","Downtrend")) | O32: =MAX(G32,O31) -> 133.061 | P32: =G32/O32 - 1 -> -0.057717889 | Q32: =TEXT(C32, "YYYY-MM") -> 2021-01 | R32: =IF(M32="","", IF(M32<0.015,"Low", IF(M32<0.03,"Medium","High"))) -> Medium
A33: 32 | B33: AAPL | C33: 2021-01-13 | D33: 125.342 | E33: 127.96 | F33: 125.079 | G33: 127.415 | H33: 88636800 | I33: 0.0162265 | J33: =(G33/G32) - 1 -> 0.016222554 | K33: =AVERAGE(G14:G33) -> 127.0704 | M33: =_xlfn.STDEV.S(J14:J33) -> 0.021904545 | N33: =IF(OR(ISBLANK(K33),ISBLANK(L33)),"",IF(K33>L33,"Uptrend","Downtrend")) | O33: =MAX(G33,O32) -> 133.061 | P33: =G33/O33 - 1 -> -0.042431667 | Q33: =TEXT(C33, "YYYY-MM") -> 2021-01 | R33: =IF(M33="","", IF(M33<0.015,"Low", IF(M33<0.03,"Medium","High"))) -> Medium
... A50: 49 | B50: AAPL | C50: 2021-02-08 | D50: 132.617 | E50: 133.523 | F50: 131.534 | G50: 133.475 | H50: 71297200 | I50: 0.00109684 | J50: =(G50/G49) - 1 -> 0.0011025441 | K50: =AVERAGE(G31:G50) -> 131.03885 | M50: =_xlfn.STDEV.S(J31:J50) -> 0.02095973 | N50: =IF(OR(ISBLANK(K50),ISBLANK(L50)),"",IF(K50>L50,"Uptrend","Downtrend")) | O50: =MAX(G50,O49) -> 139.359 | P50: =G50/O50 - 1 -> -0.042221887 | Q50: =TEXT(C50, "YYYY-MM") -> 2021-02 | R50: =IF(M50="","", IF(M50<0.015,"Low", IF(M50<0.03,"Medium","High"))) -> Medium
A51: 50 | B51: AAPL | C51: 2021-02-09 | D51: 133.192 | E51: 134.42 | F51: 132.441 | G51: 132.597 | H51: 76774200 | I51: -0.00657362 | J51: =(G51/G50) - 1 -> -0.0065780109 | K51: =AVERAGE(G32:G51) -> 131.3909 | L51: =AVERAGE(G2:G51) -> 126.83072 | M51: =_xlfn.STDEV.S(J32:J51) -> 0.020217487 | N51: =IF(OR(ISBLANK(K51),ISBLANK(L51)),"",IF(K51>L51,"Uptrend","Downtrend")) -> Uptrend | O51: =MAX(G51,O50) -> 139.359 | P51: =G51/O51 - 1 -> -0.048522162 | Q51: =TEXT(C51, "YYYY-MM") -> 2021-02 | R51: =IF(M51="","", IF(M51<0.015,"Low", IF(M51<0.03,"Medium","High"))) -> Medium
A52: 51 | B52: AAPL | C52: 2021-02-10 | D52: 133.055 | E52: 133.552 | F52: 131.027 | G52: 131.993 | H52: 73046600 | I52: -0.00455875 | J52: =(G52/G51) - 1 -> -0.0045551558 | K52: =AVERAGE(G33:G52) -> 131.7215 | L52: =AVERAGE(G3:G52) -> 127.20068 | M52: =_xlfn.STDEV.S(J33:J52) -> 0.020265341 | N52: =IF(OR(ISBLANK(K52),ISBLANK(L52)),"",IF(K52>L52,"Uptrend","Downtrend")) -> Uptrend | O52: =MAX(G52,O51) -> 139.359 | P52: =G52/O52 - 1 -> -0.052856292 | Q52: =TEXT(C52, "YYYY-MM") -> 2021-02 | R52: =IF(M52="","", IF(M52<0.015,"Low", IF(M52<0.03,"Medium","High"))) -> Medium
A53: 52 | B53: AAPL | C53: 2021-02-11 | D53: 132.49 | E53: 132.968 | F53: 130.413 | G53: 131.739 | H53: 64280000 | I53: -0.00192017 | J53: =(G53/G52) - 1 -> -0.0019243445 | K53: =AVERAGE(G34:G53) -> 131.9377 | L53: =AVERAGE(G4:G53) -> 127.51766 | M53: =_xlfn.STDEV.S(J34:J53) -> 0.020036185 | N53: =IF(OR(ISBLANK(K53),ISBLANK(L53)),"",IF(K53>L53,"Uptrend","Downtrend")) -> Uptrend | O53: =MAX(G53,O52) -> 139.359 | P53: =G53/O53 - 1 -> -0.054678923 | Q53: =TEXT(C53, "YYYY-MM") -> 2021-02 | R53: =IF(M53="","", IF(M53<0.015,"Low", IF(M53<0.03,"Medium","High"))) -> Medium
A54: 53 | B54: AAPL | C54: 2021-02-12 | D54: 130.979 | E54: 132.129 | F54: 130.335 | G54: 131.973 | H54: 60145100 | I54: 0.00177584 | J54: =(G54/G53) - 1 -> 0.0017762394 | K54: =AVERAGE(G35:G54) -> 132.26195 | L54: =AVERAGE(G5:G54) -> 127.76788 | M54: =_xlfn.STDEV.S(J35:J54) -> 0.019634528 | N54: =IF(OR(ISBLANK(K54),ISBLANK(L54)),"",IF(K54>L54,"Uptrend","Downtrend")) -> Uptrend | O54: =MAX(G54,O53) -> 139.359 | P54: =G54/O54 - 1 -> -0.052999806 | Q54: =TEXT(C54, "YYYY-MM") -> 2021-02 | R54: =IF(M54="","", IF(M54<0.015,"Low", IF(M54<0.03,"Medium","High"))) -> Medium
A55: 54 | B55: AAPL | C55: 2021-02-16 | D55: 132.09 | E55: 132.597 | F55: 129.458 | G55: 129.848 | H55: 80576300 | I55: -0.0161037 | J55: =(G55/G54) - 1 -> -0.016101778 | K55: =AVERAGE(G36:G55) -> 132.5661 | L55: =AVERAGE(G6:G55) -> 127.96858 | M55: =_xlfn.STDEV.S(J36:J55) -> 0.019745851 | N55: =IF(OR(ISBLANK(K55),ISBLANK(L55)),"",IF(K55>L55,"Uptrend","Downtrend")) -> Uptrend | O55: =MAX(G55,O54) -> 139.359 | P55: =G55/O55 - 1 -> -0.068248194 | Q55: =TEXT(C55, "YYYY-MM") -> 2021-02 | R55: =IF(M55="","", IF(M55<0.015,"Low", IF(M55<0.03,"Medium","High"))) -> Medium
A56: 55 | B56: AAPL | C56: 2021-02-17 | D56: 127.957 | E56: 128.902 | F56: 126.221 | G56: 127.557 | H56: 97918500 | I56: -0.0176441 | J56: =(G56/G55) - 1 -> -0.017643706 | K56: =AVERAGE(G37:G56) -> 132.72215 | L56: =AVERAGE(G7:G56) -> 128.1262 | M56: =_xlfn.STDEV.S(J37:J56) -> 0.020239 | N56: =IF(OR(ISBLANK(K56),ISBLANK(L56)),"",IF(K56>L56,"Uptrend","Downtrend")) -> Uptrend | O56: =MAX(G56,O55) -> 139.359 | P56: =G56/O56 - 1 -> -0.084687749 | Q56: =TEXT(C56, "YYYY-MM") -> 2021-02 | R56: =IF(M56="","", IF(M56<0.015,"Low", IF(M56<0.03,"Medium","High"))) -> Medium
A57: 56 | B57: AAPL | C57: 2021-02-18 | D57: 125.958 | E57: 126.738 | F57: 124.213 | G57: 126.455 | H57: 96856700 | I57: -0.00863658 | J57: =(G57/G56) - 1 -> -0.008639275 | K57: =AVERAGE(G38:G57) -> 132.61865 | L57: =AVERAGE(G8:G57) -> 128.2752 | M57: =_xlfn.STDEV.S(J38:J57) -> 0.018932656 | N57: =IF(OR(ISBLANK(K57),ISBLANK(L57)),"",IF(K57>L57,"Uptrend","Downtrend")) -> Uptrend | O57: =MAX(G57,O56) -> 139.359 | P57: =G57/O57 - 1 -> -0.092595383 | Q57: =TEXT(C57, "YYYY-MM") -> 2021-02 | R57: =IF(M57="","", IF(M57<0.015,"Low", IF(M57<0.03,"Medium","High"))) -> Medium
A58: 57 | B58: AAPL | C58: 2021-02-19 | D58: 126.972 | E58: 127.43 | F58: 125.568 | G58: 126.611 | H58: 87668800 | I58: 0.00123369 | J58: =(G58/G57) - 1 -> 0.0012336404 | K58: =AVERAGE(G39:G58) -> 132.2874 | L58: =AVERAGE(G9:G58) -> 128.39812 | M58: =_xlfn.STDEV.S(J39:J58) -> 0.016796452 | N58: =IF(OR(ISBLANK(K58),ISBLANK(L58)),"",IF(K58>L58,"Uptrend","Downtrend")) -> Uptrend | O58: =MAX(G58,O57) -> 139.359 | P58: =G58/O58 - 1 -> -0.091475972 | Q58: =TEXT(C58, "YYYY-MM") -> 2021-02 | R58: =IF(M58="","", IF(M58<0.015,"Low", IF(M58<0.03,"Medium","High"))) -> Medium
A59: 58 | B59: AAPL | C59: 2021-02-22 | D59: 124.798 | E59: 126.465 | F59: 122.448 | G59: 122.838 | H59: 103916400 | I59: -0.0297991 | J59: =(G59/G58) - 1 -> -0.029799938 | K59: =AVERAGE(G40:G59) -> 131.6604 | L59: =AVERAGE(G10:G59) -> 128.43332 | M59: =_xlfn.STDEV.S(J40:J59) -> 0.017264678 | N59: =IF(OR(ISBLANK(K59),ISBLANK(L59)),"",IF(K59>L59,"Uptrend","Downtrend")) -> Uptrend | O59: =MAX(G59,O58) -> 139.359 | P59: =G59/O59 - 1 -> -0.11854993 | Q59: =TEXT(C59, "YYYY-MM") -> 2021-02 | R59: =IF(M59="","", IF(M59<0.015,"Low", IF(M59<0.03,"Medium","High"))) -> Medium
A60: 59 | B60: AAPL | C60: 2021-02-23 | D60: 120.654 | E60: 123.53 | F60: 115.419 | G60: 122.702 | H60: 158273000 | I60: -0.00111113 | J60: =(G60/G59) - 1 -> -0.0011071493 | K60: =AVERAGE(G41:G60) -> 130.8392 | L60: =AVERAGE(G11:G60) -> 128.51642 | M60: =_xlfn.STDEV.S(J41:J60) -> 0.015535373 | N60: =IF(OR(ISBLANK(K60),ISBLANK(L60)),"",IF(K60>L60,"Uptrend","Downtrend")) -> Uptrend | O60: =MAX(G60,O59) -> 139.359 | P60: =G60/O60 - 1 -> -0.11952583 | Q60: =TEXT(C60, "YYYY-MM") -> 2021-02 | R60: =IF(M60="","", IF(M60<0.015,"Low", IF(M60<0.03,"Medium","High"))) -> Medium
A61: 60 | B61: AAPL | C61: 2021-02-24 | D61: 121.805 | E61: 122.409 | F61: 119.163 | G61: 122.205 | H61: 111039900 | I61: -0.00405223 | J61: =(G61/G60) - 1 -> -0.0040504637 | K61: =AVERAGE(G42:G61) -> 129.9815 | L61: =AVERAGE(G12:G61) -> 128.56116 | M61: =_xlfn.STDEV.S(J42:J61) -> 0.015436118 | N61: =IF(OR(ISBLANK(K61),ISBLANK(L61)),"",IF(K61>L61,"Uptrend","Downtrend")) -> Uptrend | O61: =MAX(G61,O60) -> 139.359 | P61: =G61/O61 - 1 -> -0.12309216 | Q61: =TEXT(C61, "YYYY-MM") -> 2021-02 | R61: =IF(M61="","", IF(M61<0.015,"Low", IF(M61<0.03,"Medium","High"))) -> Medium
...

Sheet Ticker_Info
A1: Ticker | B1: Sector | C1: Industry | D1: Market_Cap | E1: IPO_Year | F1: Country
A2: AAPL | B2: Technology | C2: Consumer Electronics | D2: Large | E2: 1980 | F2: USA
A3: TSLA | B3: Automotive | C3: Electric Vehicles | D3: Large | E3: 2010 | F3: USA
A4: NVDA | B4: Technology | C4: Semiconductors | D4: Large | E4: 1999 | F4: USA
A5: MSFT | B5: Technology | C5: Software | D5: Large | E5: 1986 | F5: USA
A6: GOOGL | B6: Technology | C6: Internet Services | D6: Large | E6: 2004 | F6: USA
A7: AMZN | B7: Consumer | C7: E-commerce | D7: Large | E7: 1997 | F7: USA
A8: META | B8: Technology | C8: Social Media | D8: Large | E8: 2012 | F8: USA
A9: JPM | B9: Finance | C9: Banking | D9: Large | E9: 1871 | F9: USA
A10: DIS | B10: Consumer | C10: Entertainment | D10: Large | E10: 1957 | F10: USA
A11: NFLX | B11: Consumer | C11: Streaming | D11: Large | E11: 2002 | F11: USA
A12: PYPL | B12: Finance | C12: Payments | D12: Large | E12: 1998 | F12: USA

Sheet Detail1
A1: Details for Count of Vol_Bucket - Vol_Bucket: High
A3: ID | B3: ticker | C3: Date | D3: Open | E3: High | F3: Low | G3: Close | H3: Volume | I3: Daily_Return | J3: Return_Excel | K3: SMA_20 | L3: SMA_50 | M3: VOL_20 | N3: Trend_20_50 | O3: Max_Close | P3: Drawdown | Q3: Date_Helper | R3: Vol_Bucket
A4: 371 | B4: AAPL | C4: 2022-05-18 | D4: 144.228 | E4: 144.728 | F4: 137.402 | G4: 138.305 | H4: 109742900 | I4: -0.0564194 | J4: -0.056421627 | K4: 152.18345 | L4: 159.66738 | M4: 0.031600993 | N4: Downtrend | O4: 178.27 | P4: -0.22418242 | Q4: 2022-05 | R4: High
A5: 372 | B5: AAPL | C5: 2022-05-19 | D5: 137.382 | E5: 139.13 | F5: 134.161 | G5: 134.897 | H5: 136095600 | I5: -0.0246413 | J5: -0.024641192 | K5: 150.7679 | L5: 159.16922 | M5: 0.031806132 | N5: Downtrend | O5: 178.27 | P5: -0.24329949 | Q5: 2022-05 | R5: High
A6: 373 | B6: AAPL | C6: 2022-05-20 | D6: 136.606 | E6: 138.187 | F6: 130.242 | G6: 135.133 | H6: 137426100 | I6: 0.00174727 | J6: 0.0017494829 | K6: 149.59115 | L6: 158.76266 | M6: 0.031571561 | N6: Downtrend | O6: 178.27 | P6: -0.24197565 | Q6: 2022-05 | R6: High
A7: 374 | B7: AAPL | C7: 2022-05-23 | D7: 135.329 | E7: 140.702 | F7: 135.192 | G7: 140.554 | H7: 117726300 | I7: 0.0401193 | J7: 0.040116034 | K7: 148.632 | L7: 158.53886 | M7: 0.033204774 | N7: Downtrend | O7: 178.27 | P7: -0.21156672 | Q7: 2022-05 | R7: High
A8: 375 | B8: AAPL | C8: 2022-05-24 | D8: 138.295 | E8: 139.435 | F8: 134.878 | G8: 137.854 | H8: 104132700 | I8: -0.0192158 | J8: -0.019209699 | K8: 147.836 | L8: 158.34168 | M8: 0.03254116 | N8: Downtrend | O8: 178.27 | P8: -0.22671229 | Q8: 2022-05 | R8: High
A9: 376 | B9: AAPL | C9: 2022-05-25 | D9: 135.958 | E9: 139.258 | F9: 135.87 | G9: 138.011 | H9: 92482700 | I9: 0.00113987 | J9: 0.0011388861 | K9: 147.05915 | L9: 158.05996 | M9: 0.032561036 | N9: Downtrend | O9: 178.27 | P9: -0.2258316 | Q9: 2022-05 | R9: High
A10: 377 | B10: AAPL | C10: 2022-05-26 | D10: 134.937 | E10: 141.762 | F10: 134.691 | G10: 141.212 | H10: 90601500 | I10: 0.0231994 | J10: 0.023193803 | K10: 146.09565 | L10: 157.754 | M10: 0.031125658 | N10: Downtrend | O10: 178.27 | P10: -0.20787569 | Q10: 2022-05 | R10: High
A11: 378 | B11: AAPL | C11: 2022-05-27 | D11: 142.794 | E11: 147.007 | F11: 142.666 | G11: 146.968 | H11: 90978500 | I11: 0.0407566 | J11: 0.040761408 | K11: 145.71365 | L11: 157.54296 | M11: 0.031908094 | N11: Downtrend | O11: 178.27 | P11: -0.17558759 | Q11: 2022-05 | R11: High
A12: 379 | B12: AAPL | C12: 2022-05-31 | D12: 146.408 | E12: 147.97 | F12: 144.218 | G12: 146.182 | H12: 103718400 | I12: -0.00534621 | J12: -0.005348103 | K12: 145.27715 | L12: 157.2503 | M12: 0.031901644 | N12: Downtrend | O12: 178.27 | P12: -0.17999663 | Q12: 2022-05 | R12: High
A13: 380 | B13: AAPL | C13: 2022-06-01 | D13: 147.223 | E13: 149.03 | F13: 145.043 | G13: 146.054 | H13: 74286600 | I13: -0.000873261 | J13: -0.0008756208 | K13: 144.75975 | L13: 156.92762 | M13: 0.03177949 | N13: Downtrend | O13: 178.27 | P13: -0.18071465 | Q13: 2022-06 | R13: High
A14: 381 | B14: AAPL | C14: 2022-06-02 | D14: 145.19 | E14: 148.569 | F14: 144.237 | G14: 148.51 | H14: 72348100 | I14: 0.0168113 | J14: 0.016815698 | K14: 144.04445 | L14: 156.58658 | M14: 0.030451482 | N14: Downtrend | O14: 178.27 | P14: -0.16693779 | Q14: 2022-06 | R14: High
A15: 493 | B15: AAPL | C15: 2022-11-10 | D15: 139.141 | E15: 144.687 | F15: 137.427 | G15: 144.687 | H15: 118854000 | I15: 0.0889748 | J15: 0.088969338 | K15: 142.5267 | L15: 145.41334 | M15: 0.034825092 | N15: Downtrend | O15: 178.27 | P15: -0.18838279 | Q15: 2022-11 | R15: High
... A920: 1305 | B920: TSLA | C920: 2021-02-08 | D920: 289.89 | E920: 292.59 | F920: 284.917 | G920: 287.807 | H920: 60485100 | I920: 0.0131303 | J920: 0.013130243 | K920: 282.7129 | L920: 246.24348 | M920: 0.033148119 | N920: Uptrend | O920: 294.363 | P920: -0.022271821 | Q920: 2021-02 | R920: High
A921: 1304 | B921: TSLA | C921: 2021-02-05 | D921: 281.667 | E921: 288.257 | F921: 279.657 | G921: 284.077 | H921: 55699800 | I921: 0.00263535 | J921: 0.0026365016 | K921: 282.98955 | M921: 0.037482975 | O921: 294.363 | P921: -0.03494325 | Q921: 2021-02 | R921: High
A922: 1303 | B922: TSLA | C922: 2021-02-04 | D922: 285 | E922: 285.5 | F922: 277.807 | G922: 283.33 | H922: 47438100 | I922: -0.00549912 | J922: -0.0055002334 | K922: 282.38635 | M922: 0.04121082 | O922: 294.363 | P922: -0.037480933 | Q922: 2021-02 | R922: High
A923: 1302 | B923: TSLA | C923: 2021-02-03 | D923: 292.34 | E923: 292.693 | F923: 284.353 | G923: 284.897 | H923: 55030500 | I923: -0.0207381 | J923: -0.020736947 | K923: 280.8195 | M923: 0.041380025 | O923: 294.363 | P923: -0.032157574 | Q923: 2021-02 | R923: High
A924: 1301 | B924: TSLA | C924: 2021-02-02 | D924: 281.56 | E924: 293.5 | F924: 280.733 | G924: 290.93 | H924: 73038600 | I924: 0.0392707 | J924: 0.03926955 | K924: 278.8265 | M924: 0.040812914 | O924: 294.363 | P924: -0.011662471 | Q924: 2021-02 | R924: High
A925: 1300 | B925: TSLA | C925: 2021-02-01 | D925: 271.43 | E925: 280.667 | F925: 265.187 | G925: 279.937 | H925: 76174200 | I925: 0.0583217 | J925: 0.058322937 | K925: 276.44285 | M925: 0.040634011 | O925: 294.363 | P925: -0.049007518 | Q925: 2021-02 | R925: High
A926: 1299 | B926: TSLA | C926: 2021-01-29 | D926: 276.667 | E926: 280.803 | F926: 260.033 | G926: 264.51 | H926: 104972400 | I926: -0.0501537 | J926: -0.05015495 | K926: 274.20715 | M926: 0.039025328 | O926: 294.363 | P926: -0.1014156 | Q926: 2021-01 | R926: High
A927: 1298 | B927: TSLA | C927: 2021-01-28 | D927: 273.333 | E927: 282.667 | F927: 267 | G927: 278.477 | H927: 79134000 | I927: -0.0332462 | J927: -0.033243882 | K927: 272.5613 | M927: 0.037327679 | O927: 294.363 | P927: -0.05396738 | Q927: 2021-01 | R927: High
A928: 1297 | B928: TSLA | C928: 2021-01-27 | D928: 290.117 | E928: 297.167 | F928: 286.22 | G928: 288.053 | H928: 82002000 | I928: -0.0214361 | J928: -0.021436118 | K928: 269.7373 | M928: 0.035856444 | O928: 294.363 | P928: -0.021436118 | Q928: 2021-01 | R928: High
A929: 1296 | B929: TSLA | C929: 2021-01-26 | D929: 297.127 | E929: 298.633 | F929: 290.533 | G929: 294.363 | H929: 69394800 | I929: 0.00259992 | J929: 0.0025987738 | K929: 266.39615 | M929: 0.034997064 | O929: 294.363 | P929: 0 | Q929: 2021-01 | R929: High
A930: 1295 | B930: TSLA | C930: 2021-01-25 | D930: 285 | E930: 300.133 | F930: 279.607 | G930: 293.6 | H930: 123520200 | I930: 0.0403478 | J930: 0.040348956 | K930: 262.7075 | M930: 0.034926862 | O930: 293.6 | P930: 0 | Q930: 2021-01 | R930: High
A931: 1294 | B931: TSLA | C931: 2021-01-22 | D931: 278.103 | E931: 282.667 | F931: 276.207 | G931: 282.213 | H931: 60199500 | I931: 0.00195264 | J931: 0.0019526881 | K931: 258.79385 | M931: 0.034488475 | O931: 293.34 | P931: -0.037932092 | Q931: 2021-01 | R931: High
A932: 1293 | B932: TSLA | C932: 2021-01-21 | D932: 285 | E932: 285.24 | F932: 280.473 | G932: 281.663 | H932: 61563300 | I932: -0.00642016 | J932: -0.0064201381 | K932: 255.35555 | M932: 0.035005374 | O932: 293.34 | P932: -0.03980705 | Q932: 2021-01 | R932: High
... A948: 1277 | B948: TSLA | C948: 2020-12-28 | D948: 224.837 | E948: 227.133 | F948: 220.267 | G948: 221.23 | H948: 96835800 | I948: 0.00290131 | J948: 0.0029013101 | K948: 209.25285 | M948: 0.039819307 | O948: 231.667 | P948: -0.045051734 | Q948: 2020-12 | R948: High

Sheet Analysis_AAPL_TSLA
A1: Summary Statistics
A2: Metric | B2: AAPL | C2: TSLA
A3: Avg Daily Return | B3: =AVERAGEIF(AAPL_TSLA!$B:$B,"AAPL",AAPL_TSLA!$I:$I) -> 0.00086857567 | C3: =AVERAGEIF(AAPL_TSLA!$B:$B,"TSLA",AAPL_TSLA!$I:$I) -> 0.0013576442
A4: Max Daily Return | B4: =_xlfn.MAXIFS(AAPL_TSLA!$I:$I,AAPL_TSLA!$B:$B,"AAPL") -> 0.153289 | C4: =_xlfn.MAXIFS(AAPL_TSLA!$I:$I,AAPL_TSLA!$B:$B,"TSLA") -> 0.2269
A5: Min Daily Return | B5: =_xlfn.MINIFS(AAPL_TSLA!$I:$I,AAPL_TSLA!$B:$B,"AAPL") -> -0.0924562 | C5: =_xlfn.MINIFS(AAPL_TSLA!$I:$I,AAPL_TSLA!$B:$B,"TSLA") -> -0.154262
A6: Avg Volatility (20d) | B6: =AVERAGEIF(AAPL_TSLA!$B:$B,"AAPL",AAPL_TSLA!$M:$M) -> 0.016515838 | C6: =AVERAGEIF(AAPL_TSLA!$B:$B,"TSLA",AAPL_TSLA!$M:$M) -> 0.036614258
A7: Max Volatility | B7: =_xlfn.MAXIFS(AAPL_TSLA!$M:$M,AAPL_TSLA!$B:$B,"AAPL") -> 0.051535414 | C7: =_xlfn.MAXIFS(AAPL_TSLA!$M:$M,AAPL_TSLA!$B:$B,"TSLA") -> 0.075753007
A8: Min Drawdown | B8: =_xlfn.MINIFS(AAPL_TSLA!$P:$P,AAPL_TSLA!$B:$B,"AAPL") -> -0.33360739 | C8: =_xlfn.MINIFS(AAPL_TSLA!$P:$P,AAPL_TSLA!$B:$B,"TSLA") -> -0.73632217
A9: Sector | B9: =VLOOKUP("AAPL",Ticker_Info!$A:$C,2,FALSE) -> Technology | C9: =VLOOKUP("TSLA",Ticker_Info!$A:$C,2,FALSE) -> Automotive
A10: Industry | B10: =VLOOKUP("AAPL",Ticker_Info!$A:$C,3,FALSE) -> Consumer Electronics | C10: =VLOOKUP("TSLA",Ticker_Info!$A:$C,3,FALSE) -> Electric Vehicles
A18: Row Labels | B18: Total Return | C18: Avg Daily Return | D18: Max Return | E18: Min Return | F18: Daily Return Count | G18: Avg Volatility
A19: AAPL | B19: 1.0900625 | C19: 0.00086857567 | D19: 0.153289 | E19: -0.0924562 | F19: 1255 | G19: 0.016515838
A20: TSLA | B20: 1.7038435 | C20: 0.0013576442 | D20: 0.2269 | E20: -0.154262 | F20: 1255 | G20: 0.036614258
A21: Grand Total | B21: 2.7939059 | C21: 0.0011131099 | D21: 0.2269 | E21: -0.154262 | F21: 2510 | G21: 0.026565048
A25: Month | B25: AAPL | C25: TSLA
A26: 2020-11 | B26: 0.0210997 | C26: -0.0310024
A27: 2020-12 | B27: 0.11204862 | C27: 0.23374823
A28: 2021-01 | B28: -0.00024886 | C28: 0.13207942
A29: 2021-02 | B29: -0.08110583 | C29: -0.14684879
A30: 2021-03 | B30: 0.0132129 | C30: 0.02359024
A31: 2021-04 | B31: 0.075414897 | C31: 0.071493306
A32: 2021-05 | B32: -0.049392718 | C32: -0.1182449
A33: 2021-06 | B33: 0.095679164 | C33: 0.090002972
A34: 2021-07 | B34: 0.06501355 | C34: 0.01529231
A35: 2021-08 | B35: 0.043042927 | C35: 0.073103536
A36: 2021-09 | B36: -0.068609143 | C36: 0.05524728
A37: 2021-10 | B37: 0.058478482 | C37: 0.3731759
... A87: Grand Total | B87: 1.0900625 | C87: 1.7038435
A90: Count of Trend_20_50 | B90: Column Labels
A91: Row Labels | B91: AAPL | C91: TSLA | D91: Grand Total
A92: Downtrend | B92: 511 | C92: 561 | D92: 1072
A93: Uptrend | B93: 696 | C93: 647 | D93: 1343
A97: Count of Vol_Bucket | B97: Column Labels
A98: Row Labels | B98: AAPL | C98: TSLA | D98: Grand Total
A99: High | B99: 46 | C99: 899 | D99: 945
A100: Low | B100: 581 | C100: 11 | D100: 592
A101: Medium | B101: 609 | C101: 326 | D101: 935
A102: Grand Total | B102: 1236 | C102: 1236 | D102: 2472
